Workbook
Name RefCcy: Config!$B$4
Name CashLabel: Config!$B$5
Name ThrSingle: Config!$B$6
Name ThrIssuer: Config!$B$7
Name DefThrCountry: Config!$B$8
Name DefThrAsset: Config!$B$9
Name CashCapPct: Config!$B$10
Name HCFXRate: Config!$B$11
Name LVCap: Config!$B$12
Name MCTrigger: Config!$B$13
Name WarnLevel: Config!$B$14
Name LVTable: Config!$A$19:$C$28
Name AssetTypeList: Config!$A$19:$A$28
Name CountryThr: Config!$A$33:$B$40
Name FXRates: Config!$A$45:$E$56
Name CcyList: Config!$A$45:$A$56
Name ExposureTot: Config!$E$83
Name FacAmt: Config!$E$75:$E$82
Name FacBucket: Config!$F$75:$F$82
Name ConcDenom: Positions!$I$2
Name ConcDenomStr: Positions!$Q$2
Name HCFXTot: HCFX!$F$15
Name HCFXTotStr: HCFX!$J$15
Name NetCV: Dashboard!$B$11
Name NetCVStr: Dashboard!$E$11

Sheet Dashboard
A1: SECURITIES-BACKED LENDING — MARGIN CALL DASHBOARD
A2: ="Reference currency: "&RefCcy&" | As of: "&TEXT(TODAY(),"yyyy-mm-dd")&" | Methodology: CV = Qty x Price x LV% -> Concentration haircut (4 dimensions) -> HCFX -> Net CV"
A4: CURRENT | D4: STRESSED (per-position shocks on Positions col AC)
A5: Total exposure (all facilities) | B5: =ExposureTot | D5: Weighted average price shock | E5: =IFERROR(Positions!$AD$205/Positions!$M$205-1,0)
A6: Gross collateral market value | B6: =Positions!$M$205 | D6: Stressed gross market value | E6: =Positions!$AD$205
A7: Collateral Value before haircuts (CV) | B7: =Positions!$P$205 | D7: Stressed CV before haircuts | E7: =Positions!$AE$205
A8: Concentration penalty | B8: =-Positions!$AB$205 | D8: Stressed concentration penalty | E8: =-(Positions!$AE$205-Positions!$AK$205)
A9: Conc Adj CV (after concentration haircut) | B9: =Positions!$AA$205 | D9: Stressed Conc Adj CV | E9: =Positions!$AK$205
A10: Currency mismatch haircut (HCFX) | B10: =-HCFXTot | D10: Stressed HCFX | E10: =-HCFXTotStr
A11: NET COLLATERAL VALUE (CV2) | B11: =Positions!$AA$205-HCFXTot | D11: STRESSED NET COLLATERAL VALUE | E11: =Positions!$AK$205-HCFXTotStr
A12: Utilisation (Exposure / Net CV) | B12: =IFERROR(ExposureTot/NetCV,0) | D12: Stressed utilisation | E12: =IFERROR(ExposureTot/NetCVStr,0)
A13: STATUS | B13: =IF(NetCV<=0,"MARGIN CALL",IF(ExposureTot/NetCV>=MCTrigger,"MARGIN CALL",IF(ExposureTot/NetCV>=WarnLevel,"WARNING","OK"))) | D13: STRESSED STATUS | E13: =IF(NetCVStr<=0,"MARGIN CALL",IF(ExposureTot/NetCVStr>=MCTrigger,"MARGIN CALL",IF(ExposureTot/NetCVStr>=WarnLevel,"WARNING","OK")))
A14: Buffer to margin call | B14: =NetCV*MCTrigger-ExposureTot | D14: Stressed buffer to margin call | E14: =NetCVStr*MCTrigger-ExposureTot
A15: Top-up required now | B15: =MAX(0,ExposureTot-NetCV*MCTrigger) | D15: Stressed top-up required | E15: =MAX(0,ExposureTot-NetCVStr*MCTrigger)
A16: Collateral fall to WARNING (uniform, approx) | B16: =IF(NetCV=0,0,MAX(0,1-ExposureTot/(WarnLevel*NetCV)))
A17: Collateral fall to MARGIN CALL (uniform, approx) | B17: =IF(NetCV=0,0,MAX(0,1-ExposureTot/(MCTrigger*NetCV)))
A18: Required CV incl. FX buffer [Exposure / (1-HCFX)] | B18: =ExposureTot/(1-HCFXRate)
A21: CONCENTRATION MONITOR (worst group per dimension)
A22: Dimension | B22: Threshold | C22: Max ratio | D22: Min Adj Factor | E22: Status | F22: Driver (worst position row)
A23: Single Counter | B23: =ThrSingle | C23: =IF(COUNT(Positions!$R$5:$R$204)=0,0,MAX(Positions!$R$5:$R$204)) | D23: =IF(COUNT(Positions!$V$5:$V$204)=0,1,MIN(Positions!$V$5:$V$204)) | E23: =IF($D23<1,"BREACH","OK") | F23: =IF($D23<1,INDEX(Positions!$B$5:$B$204,MATCH($D23,Positions!$V$5:$V$204,0)),"—")
A24: Issuer | B24: =ThrIssuer | C24: =IF(COUNT(Positions!$S$5:$S$204)=0,0,MAX(Positions!$S$5:$S$204)) | D24: =IF(COUNT(Positions!$W$5:$W$204)=0,1,MIN(Positions!$W$5:$W$204)) | E24: =IF($D24<1,"BREACH","OK") | F24: =IF($D24<1,INDEX(Positions!$B$5:$B$204,MATCH($D24,Positions!$W$5:$W$204,0)),"—")
A25: Country of Risk | B25: ="default "&TEXT(DefThrCountry,"0%")&" / overrides" | C25: =IF(COUNT(Positions!$T$5:$T$204)=0,0,MAX(Positions!$T$5:$T$204)) | D25: =IF(COUNT(Positions!$X$5:$X$204)=0,1,MIN(Positions!$X$5:$X$204)) | E25: =IF($D25<1,"BREACH","OK") | F25: =IF($D25<1,INDEX(Positions!$B$5:$B$204,MATCH($D25,Positions!$X$5:$X$204,0)),"—")
A26: Asset Type | B26: ="default "&TEXT(DefThrAsset,"0%")&" / per type" | C26: =IF(COUNT(Positions!$U$5:$U$204)=0,0,MAX(Positions!$U$5:$U$204)) | D26: =IF(COUNT(Positions!$Y$5:$Y$204)=0,1,MIN(Positions!$Y$5:$Y$204)) | E26: =IF($D26<1,"BREACH","OK") | F26: =IF($D26<1,INDEX(Positions!$B$5:$B$204,MATCH($D26,Positions!$Y$5:$Y$204,0)),"—")
A28: HOW TO READ
A29: 1. CV per position = Quantity x Price x LV% (LV defaults by asset type on Config, capped by the LV cap; override per line).
A30: 2. Concentration: ratio of each group's CV over [Marketable CV + MIN(Cash, cap% x Marketable)]. If a ratio breaches its threshold, Adj Factor = threshold / ratio; Conc Adj CV = CV x MIN of the 4 factors (conservative: the single most-penal dimension binds).
A31: 3. HCFX: collateral supporting exposure in another currency bucket is haircut (default 10%); USD & HKD share one bucket. See HCFX sheet.
A32: 4. Margin call when Exposure > Net CV x trigger. All thresholds live on Config — nothing is hardcoded.
A33: 5. Stress: enter price shocks per line in Positions col AC (e.g. -20%). The whole chain (concentration + HCFX) is recomputed under stress.

Sheet Config
A1: CONFIG — every parameter of the model lives here (nothing is hardcoded in formulas)
A3: 1. CORE PARAMETERS
A4: Reference / reporting currency | B4: USD | C4: All values converted to this currency for margin maths.
A5: Cash asset-type label | B5: Cash | C5: Rows whose Asset Type equals this label are treated as cash: LV 100%, exempt from concentration.
A6: Single Counter concentration threshold | B6: 0.3 | C6: DBS example: 30%. Adj Factor = threshold / ratio when breached.
A7: Issuer concentration threshold | B7: 0.4 | C7: DBS example: 40%.
A8: Country-of-risk threshold (default) | B8: 1 | C8: Used when the country is not in table 3 below (DBS example: most = 100%, Macao 75%).
A9: Asset-type threshold (default) | B9: 1 | C9: Used when no per-asset-type threshold is set in table 2.
A10: Cash cap in concentration denominator | B10: 0.3 | C10: Denominator = Marketable CV + MIN(Cash CV, this % x Marketable CV) — per DBS PLV report.
A11: HCFX currency-mismatch haircut | B11: 0.1 | C11: 10% haircut on CV allocated to exposure in a different currency bucket.
A12: LV cap (marketable securities) | B12: 0.75 | C12: Regulatory LV cap (e.g. 75% cap in HK for equities/ELNs). Applied to non-cash rows.
A13: Margin call trigger (utilisation of net CV) | B13: 1 | C13: Margin call when Exposure > Net CV x this trigger.
A14: Early-warning utilisation level | B14: 0.9 | C14: Status shows 'Warning' above this utilisation.
A17: 2. ASSET TYPES — default Lending Value % and concentration threshold
A18: Asset Type | B18: Default LV % | C18: Conc. Threshold % | D18: Notes
A19: Listed Equity | B19: 0.7 | C19: 1 | D19: LV capped by parameter 'LV cap' above
A20: Bond | B20: 0.75 | C20: 1
A21: Fund / ETF | B21: 0.65 | C21: 1
A22: Structured Product | B22: 0.6 | C22: 1 | D22: e.g. FCN / ELN
A23: Cash | B23: 1 | C23: 1 | D23: Exempt from concentration; HCFX still applies
A31: 3. COUNTRY-OF-RISK THRESHOLD OVERRIDES (all other countries use the default in section 1)
A32: Country | B32: Threshold %
A33: Macao | B33: 0.75
A43: 4. FX RATES & HCFX CURRENCY BUCKETS (rate = reference-ccy per 1 unit; live rate overrides manual when present)
A44: Currency | B44: Manual rate | C44: Live rate (optional) | D44: Rate used | E44: HCFX Bucket | F44: Note
A45: USD | B45: 1 | D45: =IF($A45="","",IF(ISNUMBER($C45),$C45,$B45)) | E45: USD&HKD | F45: Reference currency
A46: HKD | B46: 0.1282 | D46: =IF($A46="","",IF(ISNUMBER($C46),$C46,$B46)) | E46: USD&HKD | F46: USD/HKD pegged — one bucket, no HCFX between them
A47: CHF | B47: 1.2349 | D47: =IF($A47="","",IF(ISNUMBER($C47),$C47,$B47)) | E47: CHF
A48: EUR | B48: 1.17 | D48: =IF($A48="","",IF(ISNUMBER($C48),$C48,$B48)) | E48: EUR
A49: GBP | B49: 1.34 | D49: =IF($A49="","",IF(ISNUMBER($C49),$C49,$B49)) | E49: GBP
A50: SGD | B50: 0.78 | D50: =IF($A50="","",IF(ISNUMBER($C50),$C50,$B50)) | E50: SGD
A51: JPY | B51: 0.0067 | D51: =IF($A51="","",IF(ISNUMBER($C51),$C51,$B51)) | E51: JPY
A52: CNH | B52: 0.139 | D52: =IF($A52="","",IF(ISNUMBER($C52),$C52,$B52)) | E52: CNH
D53: =IF($A53="","",IF(ISNUMBER($C53),$C53,$B53))
D54: =IF($A54="","",IF(ISNUMBER($C54),$C54,$B54))
D55: =IF($A55="","",IF(ISNUMBER($C55),$C55,$B55))
D56: =IF($A56="","",IF(ISNUMBER($C56),$C56,$B56))
A59: 5. HCFX BUCKET LIST (drives the HCFX sheet — add a row here when you add a new bucket in section 4)
A60: Bucket
A61: USD&HKD
...

Sheet Positions
A1: POSITIONS & COLLATERAL ENGINE — paste any portfolio here; everything below row 4 recalculates
B2: Marketable CV: | C2: =SUMIFS($P$5:$P$204,$D$5:$D$204,"<>"&CashLabel,$B$5:$B$204,"<>") | D2: Cash CV: | E2: =SUMIFS($P$5:$P$204,$D$5:$D$204,CashLabel) | F2: Cash recognised: | G2: =MIN($E$2,$C$2*CashCapPct) | H2: Conc denominator: | I2: =$C$2+$G$2 | J2: Str. marketable CV: | K2: =SUMIFS($AE$5:$AE$204,$D$5:$D$204,"<>"&CashLabel,$B$5:$B$204,"<>") | L2: Str. cash CV: | M2: =SUMIFS($AE$5:$AE$204,$D$5:$D$204,CashLabel) | N2: Str. cash recognised: | O2: =MIN($M$2,$K$2*CashCapPct) | P2: Str. denominator: | Q2: =$K$2+$O$2
B3: Denominator = Marketable CV + MIN(Cash CV, cap% x Marketable CV) | cash rows: LV 100%, concentration-exempt, HCFX still applies
A4: Line | B4: Security / Position | C4: Ticker | D4: Asset Type | E4: Issuer | F4: Country of Risk | G4: Ccy | H4: Quantity | I4: Price (manual) | J4: Price (live, optional) | K4: Price used | L4: FX rate used | M4: Market Value (ref ccy) | N4: LV% override | O4: LV% used | P4: Collateral Value (CV) | Q4: HCFX Bucket | R4: Single-Counter ratio | S4: Issuer ratio | T4: Country ratio | U4: Asset-Type ratio | V4: Adj Factor Single | W4: Adj Factor Issuer | X4: Adj Factor Country | Y4: Adj Factor Asset | Z4: Min Adj Factor | AA4: Conc Adj CV | AB4: Concentration Penalty | AC4: Price shock % (input) | AD4: Stressed MV | AE4: Stressed CV | AF4: s-Single ratio | AG4: s-Issuer ratio | AH4: s-Country ratio | AI4: s-Asset ratio | AJ4: s-Min Factor | AK4: Stressed Conc Adj CV
A5: =IF($B5="","",ROW()-4) | B5: Meta Platforms Inc | C5: META | D5: Listed Equity | E5: Meta Platforms Inc | F5: United States | G5: USD | H5: 2800 | I5: 542.87 | K5: =IF($B5="","",IF(ISNUMBER($J5),$J5,$I5)) | L5: =IF($B5="","",IFERROR(VLOOKUP($G5,FXRates,4,FALSE),1)) | M5: =IF($B5="","",$H5*$K5*$L5) | O5: =IF($B5="","",IF($D5=CashLabel,IF(ISNUMBER($N5),$N5,1),MIN(IF(ISNUMBER($N5),$N5,IFERROR(VLOOKUP($D5,LVTable,2,FALSE),0)),LVCap))) | P5: =IF($B5="","",$M5*$O5) | Q5: =IF($B5="","",IFERROR(VLOOKUP($G5,FXRates,5,FALSE),$G5)) | R5: =IF($B5="","",IF($D5=CashLabel,"",SUMIFS($P$5:$P$204,$B$5:$B$204,$B5,$D$5:$D$204,"<>"&CashLabel)/ConcDenom)) | S5: =IF($B5="","",IF($D5=CashLabel,"",SUMIFS($P$5:$P$204,$E$5:$E$204,$E5,$D$5:$D$204,"<>"&CashLabel)/ConcDenom)) | T5: =IF($B5="","",IF($D5=CashLabel,"",SUMIFS($P$5:$P$204,$F$5:$F$204,$F5,$D$5:$D$204,"<>"&CashLabel)/ConcDenom)) | U5: =IF($B5="","",IF($D5=CashLabel,"",SUMIFS($P$5:$P$204,$D$5:$D$204,$D5,$D$5:$D$204,"<>"&CashLabel)/ConcDenom)) | V5: =IF($B5="","",IF($D5=CashLabel,1,IF($R5>ThrSingle,ThrSingle/$R5,1))) | W5: =IF($B5="","",IF($D5=CashLabel,1,IF($S5>ThrIssuer,ThrIssuer/$S5,1))) | X5: =IF($B5="","",IF($D5=CashLabel,1,IF($T5>IFERROR(VLOOKUP($F5,CountryThr,2,FALSE),DefThrCountry),IFERROR(VLOOKUP($F5,CountryThr,2,FALSE),DefThrCountry)/$T5,1))) | Y5: =IF($B5="","",IF($D5=CashLabel,1,IF($U5>IFERROR(VLOOKUP($D5,LVTable,3,FALSE),DefThrAsset),IFERROR(VLOOKUP($D5,LVTable,3,FALSE),DefThrAsset)/$U5,1))) | Z5: =IF($B5="","",IF($D5=CashLabel,1,MIN($V5:$Y5))) | AA5: =IF($B5="","",$P5*$Z5) | AB5: =IF($B5="","",$P5-$AA5) | AC5: -0.25 | AD5: =IF($B5="","",$M5*(1+IF(ISNUMBER($AC5),$AC5,0))) | AE5: =IF($B5="","",$AD5*$O5) | AF5: =IF($B5="","",IF($D5=CashLabel,"",SUMIFS($AE$5:$AE$204,$B$5:$B$204,$B5,$D$5:$D$204,"<>"&CashLabel)/ConcDenomStr)) | AG5: =IF($B5="","",IF($D5=CashLabel,"",SUMIFS($AE$5:$AE$204,$E$5:$E$204,$E5,$D$5:$D$204,"<>"&CashLabel)/ConcDenomStr)) | AH5: =IF($B5="","",IF($D5=CashLabel,"",SUMIFS($AE$5:$AE$204,$F$5:$F$204,$F5,$D$5:$D$204,"<>"&CashLabel)/ConcDenomStr)) | AI5: =IF($B5="","",IF($D5=CashLabel,"",SUMIFS($AE$5:$AE$204,$D$5:$D$204,$D5,$D$5:$D$204,"<>"&CashLabel)/ConcDenomStr)) | AJ5: =IF($B5="","",IF($D5=CashLabel,1,MIN(IF($AF5>ThrSingle,ThrSingle/$AF5,1),IF($AG5>ThrIssuer,ThrIssuer/$AG5,1),IF($AH5>IFERROR(VLOOKUP($F5,CountryThr,2,FALSE),DefThrCountry),IFERROR(VLOOKUP($F5,CountryThr,2,FALSE),DefThrCountry)/$AH5,1),IF($AI5>IFERROR(VLOOKUP($D5,LVTable,3,FALSE),DefThrAsset),IFERROR(VLOOKUP($D5,LVTable,3,FALSE),DefThrAsset)/$AI5,1)))) | AK5: =IF($B5="","",$AE5*$AJ5)
A6: =IF($B6="","",ROW()-4) | B6: Roblox Corp | C6: RBLX | D6: Listed Equity | E6: Roblox Corp | F6: United States | G6: USD | H6: 9800 | I6: 46.39 | K6: =IF($B6="","",IF(ISNUMBER($J6),$J6,$I6)) | L6: =IF($B6="","",IFERROR(VLOOKUP($G6,FXRates,4,FALSE),1)) | M6: =IF($B6="","",$H6*$K6*$L6) | O6: =IF($B6="","",IF($D6=CashLabel,IF(ISNUMBER($N6),$N6,1),MIN(IF(ISNUMBER($N6),$N6,IFERROR(VLOOKUP($D6,LVTable,2,FALSE),0)),LVCap))) | P6: =IF($B6="","",$M6*$O6) | Q6: =IF($B6="","",IFERROR(VLOOKUP($G6,FXRates,5,FALSE),$G6)) | R6: =IF($B6="","",IF($D6=CashLabel,"",SUMIFS($P$5:$P$204,$B$5:$B$204,$B6,$D$5:$D$204,"<>"&CashLabel)/ConcDenom)) | S6: =IF($B6="","",IF($D6=CashLabel,"",SUMIFS($P$5:$P$204,$E$5:$E$204,$E6,$D$5:$D$204,"<>"&CashLabel)/ConcDenom)) | T6: =IF($B6="","",IF($D6=CashLabel,"",SUMIFS($P$5:$P$204,$F$5:$F$204,$F6,$D$5:$D$204,"<>"&CashLabel)/ConcDenom)) | U6: =IF($B6="","",IF($D6=CashLabel,"",SUMIFS($P$5:$P$204,$D$5:$D$204,$D6,$D$5:$D$204,"<>"&CashLabel)/ConcDenom)) | V6: =IF($B6="","",IF($D6=CashLabel,1,IF($R6>ThrSingle,ThrSingle/$R6,1))) | W6: =IF($B6="","",IF($D6=CashLabel,1,IF($S6>ThrIssuer,ThrIssuer/$S6,1))) | X6: =IF($B6="","",IF($D6=CashLabel,1,IF($T6>IFERROR(VLOOKUP($F6,CountryThr,2,FALSE),DefThrCountry),IFERROR(VLOOKUP($F6,CountryThr,2,FALSE),DefThrCountry)/$T6,1))) | Y6: =IF($B6="","",IF($D6=CashLabel,1,IF($U6>IFERROR(VLOOKUP($D6,LVTable,3,FALSE),DefThrAsset),IFERROR(VLOOKUP($D6,LVTable,3,FALSE),DefThrAsset)/$U6,1))) | Z6: =IF($B6="","",IF($D6=CashLabel,1,MIN($V6:$Y6))) | AA6: =IF($B6="","",$P6*$Z6) | AB6: =IF($B6="","",$P6-$AA6) | AC6: -0.25 | AD6: =IF($B6="","",$M6*(1+IF(ISNUMBER($AC6),$AC6,0))) | AE6: =IF($B6="","",$AD6*$O6) | AF6: =IF($B6="","",IF($D6=CashLabel,"",SUMIFS($AE$5:$AE$204,$B$5:$B$204,$B6,$D$5:$D$204,"<>"&CashLabel)/ConcDenomStr)) | AG6: =IF($B6="","",IF($D6=CashLabel,"",SUMIFS($AE$5:$AE$204,$E$5:$E$204,$E6,$D$5:$D$204,"<>"&CashLabel)/ConcDenomStr)) | AH6: =IF($B6="","",IF($D6=CashLabel,"",SUMIFS($AE$5:$AE$204,$F$5:$F$204,$F6,$D$5:$D$204,"<>"&CashLabel)/ConcDenomStr)) | AI6: =IF($B6="","",IF($D6=CashLabel,"",SUMIFS($AE$5:$AE$204,$D$5:$D$204,$D6,$D$5:$D$204,"<>"&CashLabel)/ConcDenomStr)) | AJ6: =IF($B6="","",IF($D6=CashLabel,1,MIN(IF($AF6>ThrSingle,ThrSingle/$AF6,1),IF($AG6>ThrIssuer,ThrIssuer/$AG6,1),IF($AH6>IFERROR(VLOOKUP($F6,CountryThr,2,FALSE),DefThrCountry),IFERROR(VLOOKUP($F6,CountryThr,2,FALSE),DefThrCountry)/$AH6,1),IF($AI6>IFERROR(VLOOKUP($D6,LVTable,3,FALSE),DefThrAsset),IFERROR(VLOOKUP($D6,LVTable,3,FALSE),DefThrAsset)/$AI6,1)))) | AK6: =IF($B6="","",$AE6*$AJ6)
A7: =IF($B7="","",ROW()-4) | B7: FCN on HOOD (Robinhood) | D7: Structured Product | E7: Issuing Bank A | F7: United States | G7: USD | H7: 1 | I7: 600000 | K7: =IF($B7="","",IF(ISNUMBER($J7),$J7,$I7)) | L7: =IF($B7="","",IFERROR(VLOOKUP($G7,FXRates,4,FALSE),1)) | M7: =IF($B7="","",$H7*$K7*$L7) | O7: =IF($B7="","",IF($D7=CashLabel,IF(ISNUMBER($N7),$N7,1),MIN(IF(ISNUMBER($N7),$N7,IFERROR(VLOOKUP($D7,LVTable,2,FALSE),0)),LVCap))) | P7: =IF($B7="","",$M7*$O7) | Q7: =IF($B7="","",IFERROR(VLOOKUP($G7,FXRates,5,FALSE),$G7)) | R7: =IF($B7="","",IF($D7=CashLabel,"",SUMIFS($P$5:$P$204,$B$5:$B$204,$B7,$D$5:$D$204,"<>"&CashLabel)/ConcDenom)) | S7: =IF($B7="","",IF($D7=CashLabel,"",SUMIFS($P$5:$P$204,$E$5:$E$204,$E7,$D$5:$D$204,"<>"&CashLabel)/ConcDenom)) | T7: =IF($B7="","",IF($D7=CashLabel,"",SUMIFS($P$5:$P$204,$F$5:$F$204,$F7,$D$5:$D$204,"<>"&CashLabel)/ConcDenom)) | U7: =IF($B7="","",IF($D7=CashLabel,"",SUMIFS($P$5:$P$204,$D$5:$D$204,$D7,$D$5:$D$204,"<>"&CashLabel)/ConcDenom)) | V7: =IF($B7="","",IF($D7=CashLabel,1,IF($R7>ThrSingle,ThrSingle/$R7,1))) | W7: =IF($B7="","",IF($D7=CashLabel,1,IF($S7>ThrIssuer,ThrIssuer/$S7,1))) | X7: =IF($B7="","",IF($D7=CashLabel,1,IF($T7>IFERROR(VLOOKUP($F7,CountryThr,2,FALSE),DefThrCountry),IFERROR(VLOOKUP($F7,CountryThr,2,FALSE),DefThrCountry)/$T7,1))) | Y7: =IF($B7="","",IF($D7=CashLabel,1,IF($U7>IFERROR(VLOOKUP($D7,LVTable,3,FALSE),DefThrAsset),IFERROR(VLOOKUP($D7,LVTable,3,FALSE),DefThrAsset)/$U7,1))) | Z7: =IF($B7="","",IF($D7=CashLabel,1,MIN($V7:$Y7))) | AA7: =IF($B7="","",$P7*$Z7) | AB7: =IF($B7="","",$P7-$AA7) | AC7: -0.15 | AD7: =IF($B7="","",$M7*(1+IF(ISNUMBER($AC7),$AC7,0))) | AE7: =IF($B7="","",$AD7*$O7) | AF7: =IF($B7="","",IF($D7=CashLabel,"",SUMIFS($AE$5:$AE$204,$B$5:$B$204,$B7,$D$5:$D$204,"<>"&CashLabel)/ConcDenomStr)) | AG7: =IF($B7="","",IF($D7=CashLabel,"",SUMIFS($AE$5:$AE$204,$E$5:$E$204,$E7,$D$5:$D$204,"<>"&CashLabel)/ConcDenomStr)) | AH7: =IF($B7="","",IF($D7=CashLabel,"",SUMIFS($AE$5:$AE$204,$F$5:$F$204,$F7,$D$5:$D$204,"<>"&CashLabel)/ConcDenomStr)) | AI7: =IF($B7="","",IF($D7=CashLabel,"",SUMIFS($AE$5:$AE$204,$D$5:$D$204,$D7,$D$5:$D$204,"<>"&CashLabel)/ConcDenomStr)) | AJ7: =IF($B7="","",IF($D7=CashLabel,1,MIN(IF($AF7>ThrSingle,ThrSingle/$AF7,1),IF($AG7>ThrIssuer,ThrIssuer/$AG7,1),IF($AH7>IFERROR(VLOOKUP($F7,CountryThr,2,FALSE),DefThrCountry),IFERROR(VLOOKUP($F7,CountryThr,2,FALSE),DefThrCountry)/$AH7,1),IF($AI7>IFERROR(VLOOKUP($D7,LVTable,3,FALSE),DefThrAsset),IFERROR(VLOOKUP($D7,LVTable,3,FALSE),DefThrAsset)/$AI7,1)))) | AK7: =IF($B7="","",$AE7*$AJ7)
A8: =IF($B8="","",ROW()-4) | B8: FCN on RBLX (Roblox) | D8: Structured Product | E8: Issuing Bank A | F8: United States | G8: USD | H8: 1 | I8: 600000 | K8: =IF($B8="","",IF(ISNUMBER($J8),$J8,$I8)) | L8: =IF($B8="","",IFERROR(VLOOKUP($G8,FXRates,4,FALSE),1)) | M8: =IF($B8="","",$H8*$K8*$L8) | O8: =IF($B8="","",IF($D8=CashLabel,IF(ISNUMBER($N8),$N8,1),MIN(IF(ISNUMBER($N8),$N8,IFERROR(VLOOKUP($D8,LVTable,2,FALSE),0)),LVCap))) | P8: =IF($B8="","",$M8*$O8) | Q8: =IF($B8="","",IFERROR(VLOOKUP($G8,FXRates,5,FALSE),$G8)) | R8: =IF($B8="","",IF($D8=CashLabel,"",SUMIFS($P$5:$P$204,$B$5:$B$204,$B8,$D$5:$D$204,"<>"&CashLabel)/ConcDenom)) | S8: =IF($B8="","",IF($D8=CashLabel,"",SUMIFS($P$5:$P$204,$E$5:$E$204,$E8,$D$5:$D$204,"<>"&CashLabel)/ConcDenom)) | T8: =IF($B8="","",IF($D8=CashLabel,"",SUMIFS($P$5:$P$204,$F$5:$F$204,$F8,$D$5:$D$204,"<>"&CashLabel)/ConcDenom)) | U8: =IF($B8="","",IF($D8=CashLabel,"",SUMIFS($P$5:$P$204,$D$5:$D$204,$D8,$D$5:$D$204,"<>"&CashLabel)/ConcDenom)) | V8: =IF($B8="","",IF($D8=CashLabel,1,IF($R8>ThrSingle,ThrSingle/$R8,1))) | W8: =IF($B8="","",IF($D8=CashLabel,1,IF($S8>ThrIssuer,ThrIssuer/$S8,1))) | X8: =IF($B8="","",IF($D8=CashLabel,1,IF($T8>IFERROR(VLOOKUP($F8,CountryThr,2,FALSE),DefThrCountry),IFERROR(VLOOKUP($F8,CountryThr,2,FALSE),DefThrCountry)/$T8,1))) | Y8: =IF($B8="","",IF($D8=CashLabel,1,IF($U8>IFERROR(VLOOKUP($D8,LVTable,3,FALSE),DefThrAsset),IFERROR(VLOOKUP($D8,LVTable,3,FALSE),DefThrAsset)/$U8,1))) | Z8: =IF($B8="","",IF($D8=CashLabel,1,MIN($V8:$Y8))) | AA8: =IF($B8="","",$P8*$Z8) | AB8: =IF($B8="","",$P8-$AA8) | AC8: -0.15 | AD8: =IF($B8="","",$M8*(1+IF(ISNUMBER($AC8),$AC8,0))) | AE8: =IF($B8="","",$AD8*$O8) | AF8: =IF($B8="","",IF($D8=CashLabel,"",SUMIFS($AE$5:$AE$204,$B$5:$B$204,$B8,$D$5:$D$204,"<>"&CashLabel)/ConcDenomStr)) | AG8: =IF($B8="","",IF($D8=CashLabel,"",SUMIFS($AE$5:$AE$204,$E$5:$E$204,$E8,$D$5:$D$204,"<>"&CashLabel)/ConcDenomStr)) | AH8: =IF($B8="","",IF($D8=CashLabel,"",SUMIFS($AE$5:$AE$204,$F$5:$F$204,$F8,$D$5:$D$204,"<>"&CashLabel)/ConcDenomStr)) | AI8: =IF($B8="","",IF($D8=CashLabel,"",SUMIFS($AE$5:$AE$204,$D$5:$D$204,$D8,$D$5:$D$204,"<>"&CashLabel)/ConcDenomStr)) | AJ8: =IF($B8="","",IF($D8=CashLabel,1,MIN(IF($AF8>ThrSingle,ThrSingle/$AF8,1),IF($AG8>ThrIssuer,ThrIssuer/$AG8,1),IF($AH8>IFERROR(VLOOKUP($F8,CountryThr,2,FALSE),DefThrCountry),IFERROR(VLOOKUP($F8,CountryThr,2,FALSE),DefThrCountry)/$AH8,1),IF($AI8>IFERROR(VLOOKUP($D8,LVTable,3,FALSE),DefThrAsset),IFERROR(VLOOKUP($D8,LVTable,3,FALSE),DefThrAsset)/$AI8,1)))) | AK8: =IF($B8="","",$AE8*$AJ8)
A9: =IF($B9="","",ROW()-4) | B9: Time deposit USD | D9: Cash | E9: Deposit Bank | F9: Hong Kong | G9: USD | H9: 1 | I9: 708197.43 | K9: =IF($B9="","",IF(ISNUMBER($J9),$J9,$I9)) | L9: =IF($B9="","",IFERROR(VLOOKUP($G9,FXRates,4,FALSE),1)) | M9: =IF($B9="","",$H9*$K9*$L9) | O9: =IF($B9="","",IF($D9=CashLabel,IF(ISNUMBER($N9),$N9,1),MIN(IF(ISNUMBER($N9),$N9,IFERROR(VLOOKUP($D9,LVTable,2,FALSE),0)),LVCap))) | P9: =IF($B9="","",$M9*$O9) | Q9: =IF($B9="","",IFERROR(VLOOKUP($G9,FXRates,5,FALSE),$G9)) | R9: =IF($B9="","",IF($D9=CashLabel,"",SUMIFS($P$5:$P$204,$B$5:$B$204,$B9,$D$5:$D$204,"<>"&CashLabel)/ConcDenom)) | S9: =IF($B9="","",IF($D9=CashLabel,"",SUMIFS($P$5:$P$204,$E$5:$E$204,$E9,$D$5:$D$204,"<>"&CashLabel)/ConcDenom)) | T9: =IF($B9="","",IF($D9=CashLabel,"",SUMIFS($P$5:$P$204,$F$5:$F$204,$F9,$D$5:$D$204,"<>"&CashLabel)/ConcDenom)) | U9: =IF($B9="","",IF($D9=CashLabel,"",SUMIFS($P$5:$P$204,$D$5:$D$204,$D9,$D$5:$D$204,"<>"&CashLabel)/ConcDenom)) | V9: =IF($B9="","",IF($D9=CashLabel,1,IF($R9>ThrSingle,ThrSingle/$R9,1))) | W9: =IF($B9="","",IF($D9=CashLabel,1,IF($S9>ThrIssuer,ThrIssuer/$S9,1))) | X9: =IF($B9="","",IF($D9=CashLabel,1,IF($T9>IFERROR(VLOOKUP($F9,CountryThr,2,FALSE),DefThrCountry),IFERROR(VLOOKUP($F9,CountryThr,2,FALSE),DefThrCountry)/$T9,1))) | Y9: =IF($B9="","",IF($D9=CashLabel,1,IF($U9>IFERROR(VLOOKUP($D9,LVTable,3,FALSE),DefThrAsset),IFERROR(VLOOKUP($D9,LVTable,3,FALSE),DefThrAsset)/$U9,1))) | Z9: =IF($B9="","",IF($D9=CashLabel,1,MIN($V9:$Y9))) | AA9: =IF($B9="","",$P9*$Z9) | AB9: =IF($B9="","",$P9-$AA9) | AC9: 0 | AD9: =IF($B9="","",$M9*(1+IF(ISNUMBER($AC9),$AC9,0))) | AE9: =IF($B9="","",$AD9*$O9) | AF9: =IF($B9="","",IF($D9=CashLabel,"",SUMIFS($AE$5:$AE$204,$B$5:$B$204,$B9,$D$5:$D$204,"<>"&CashLabel)/ConcDenomStr)) | AG9: =IF($B9="","",IF($D9=CashLabel,"",SUMIFS($AE$5:$AE$204,$E$5:$E$204,$E9,$D$5:$D$204,"<>"&CashLabel)/ConcDenomStr)) | AH9: =IF($B9="","",IF($D9=CashLabel,"",SUMIFS($AE$5:$AE$204,$F$5:$F$204,$F9,$D$5:$D$204,"<>"&CashLabel)/ConcDenomStr)) | AI9: =IF($B9="","",IF($D9=CashLabel,"",SUMIFS($AE$5:$AE$204,$D$5:$D$204,$D9,$D$5:$D$204,"<>"&CashLabel)/ConcDenomStr)) | AJ9: =IF($B9="","",IF($D9=CashLabel,1,MIN(IF($AF9>ThrSingle,ThrSingle/$AF9,1),IF($AG9>ThrIssuer,ThrIssuer/$AG9,1),IF($AH9>IFERROR(VLOOKUP($F9,CountryThr,2,FALSE),DefThrCountry),IFERROR(VLOOKUP($F9,CountryThr,2,FALSE),DefThrCountry)/$AH9,1),IF($AI9>IFERROR(VLOOKUP($D9,LVTable,3,FALSE),DefThrAsset),IFERROR(VLOOKUP($D9,LVTable,3,FALSE),DefThrAsset)/$AI9,1)))) | AK9: =IF($B9="","",$AE9*$AJ9)
A10: =IF($B10="","",ROW()-4) | B10: Time deposit HKD | D10: Cash | E10: Deposit Bank | F10: Hong Kong | G10: HKD | H10: 1 | I10: 824747.59 | K10: =IF($B10="","",IF(ISNUMBER($J10),$J10,$I10)) | L10: =IF($B10="","",IFERROR(VLOOKUP($G10,FXRates,4,FALSE),1)) | M10: =IF($B10="","",$H10*$K10*$L10) | O10: =IF($B10="","",IF($D10=CashLabel,IF(ISNUMBER($N10),$N10,1),MIN(IF(ISNUMBER($N10),$N10,IFERROR(VLOOKUP($D10,LVTable,2,FALSE),0)),LVCap))) | P10: =IF($B10="","",$M10*$O10) | Q10: =IF($B10="","",IFERROR(VLOOKUP($G10,FXRates,5,FALSE),$G10)) | R10: =IF($B10="","",IF($D10=CashLabel,"",SUMIFS($P$5:$P$204,$B$5:$B$204,$B10,$D$5:$D$204,"<>"&CashLabel)/ConcDenom)) | S10: =IF($B10="","",IF($D10=CashLabel,"",SUMIFS($P$5:$P$204,$E$5:$E$204,$E10,$D$5:$D$204,"<>"&CashLabel)/ConcDenom)) | T10: =IF($B10="","",IF($D10=CashLabel,"",SUMIFS($P$5:$P$204,$F$5:$F$204,$F10,$D$5:$D$204,"<>"&CashLabel)/ConcDenom)) | U10: =IF($B10="","",IF($D10=CashLabel,"",SUMIFS($P$5:$P$204,$D$5:$D$204,$D10,$D$5:$D$204,"<>"&CashLabel)/ConcDenom)) | V10: =IF($B10="","",IF($D10=CashLabel,1,IF($R10>ThrSingle,ThrSingle/$R10,1))) | W10: =IF($B10="","",IF($D10=CashLabel,1,IF($S10>ThrIssuer,ThrIssuer/$S10,1))) | X10: =IF($B10="","",IF($D10=CashLabel,1,IF($T10>IFERROR(VLOOKUP($F10,CountryThr,2,FALSE),DefThrCountry),IFERROR(VLOOKUP($F10,CountryThr,2,FALSE),DefThrCountry)/$T10,1))) | Y10: =IF($B10="","",IF($D10=CashLabel,1,IF($U10>IFERROR(VLOOKUP($D10,LVTable,3,FALSE),DefThrAsset),IFERROR(VLOOKUP($D10,LVTable,3,FALSE),DefThrAsset)/$U10,1))) | Z10: =IF($B10="","",IF($D10=CashLabel,1,MIN($V10:$Y10))) | AA10: =IF($B10="","",$P10*$Z10) | AB10: =IF($B10="","",$P10-$AA10) | AC10: 0 | AD10: =IF($B10="","",$M10*(1+IF(ISNUMBER($AC10),$AC10,0))) | AE10: =IF($B10="","",$AD10*$O10) | AF10: =IF($B10="","",IF($D10=CashLabel,"",SUMIFS($AE$5:$AE$204,$B$5:$B$204,$B10,$D$5:$D$204,"<>"&CashLabel)/ConcDenomStr)) | AG10: =IF($B10="","",IF($D10=CashLabel,"",SUMIFS($AE$5:$AE$204,$E$5:$E$204,$E10,$D$5:$D$204,"<>"&CashLabel)/ConcDenomStr)) | AH10: =IF($B10="","",IF($D10=CashLabel,"",SUMIFS($AE$5:$AE$204,$F$5:$F$204,$F10,$D$5:$D$204,"<>"&CashLabel)/ConcDenomStr)) | AI10: =IF($B10="","",IF($D10=CashLabel,"",SUMIFS($AE$5:$AE$204,$D$5:$D$204,$D10,$D$5:$D$204,"<>"&CashLabel)/ConcDenomStr)) | AJ10: =IF($B10="","",IF($D10=CashLabel,1,MIN(IF($AF10>ThrSingle,ThrSingle/$AF10,1),IF($AG10>ThrIssuer,ThrIssuer/$AG10,1),IF($AH10>IFERROR(VLOOKUP($F10,CountryThr,2,FALSE),DefThrCountry),IFERROR(VLOOKUP($F10,CountryThr,2,FALSE),DefThrCountry)/$AH10,1),IF($AI10>IFERROR(VLOOKUP($D10,LVTable,3,FALSE),DefThrAsset),IFERROR(VLOOKUP($D10,LVTable,3,FALSE),DefThrAsset)/$AI10,1)))) | AK10: =IF($B10="","",$AE10*$AJ10)
A11: =IF($B11="","",ROW()-4) | B11: Fenghe Asia Fund (USTE) | D11: Fund / ETF | E11: Fenghe Asset Management | F11: Singapore | G11: USD | H11: 1 | I11: 1180.82 | K11: =IF($B11="","",IF(ISNUMBER($J11),$J11,$I11)) | L11: =IF($B11="","",IFERROR(VLOOKUP($G11,FXRates,4,FALSE),1)) | M11: =IF($B11="","",$H11*$K11*$L11) | O11: =IF($B11="","",IF($D11=CashLabel,IF(ISNUMBER($N11),$N11,1),MIN(IF(ISNUMBER($N11),$N11,IFERROR(VLOOKUP($D11,LVTable,2,FALSE),0)),LVCap))) | P11: =IF($B11="","",$M11*$O11) | Q11: =IF($B11="","",IFERROR(VLOOKUP($G11,FXRates,5,FALSE),$G11)) | R11: =IF($B11="","",IF($D11=CashLabel,"",SUMIFS($P$5:$P$204,$B$5:$B$204,$B11,$D$5:$D$204,"<>"&CashLabel)/ConcDenom)) | S11: =IF($B11="","",IF($D11=CashLabel,"",SUMIFS($P$5:$P$204,$E$5:$E$204,$E11,$D$5:$D$204,"<>"&CashLabel)/ConcDenom)) | T11: =IF($B11="","",IF($D11=CashLabel,"",SUMIFS($P$5:$P$204,$F$5:$F$204,$F11,$D$5:$D$204,"<>"&CashLabel)/ConcDenom)) | U11: =IF($B11="","",IF($D11=CashLabel,"",SUMIFS($P$5:$P$204,$D$5:$D$204,$D11,$D$5:$D$204,"<>"&CashLabel)/ConcDenom)) | V11: =IF($B11="","",IF($D11=CashLabel,1,IF($R11>ThrSingle,ThrSingle/$R11,1))) | W11: =IF($B11="","",IF($D11=CashLabel,1,IF($S11>ThrIssuer,ThrIssuer/$S11,1))) | X11: =IF($B11="","",IF($D11=CashLabel,1,IF($T11>IFERROR(VLOOKUP($F11,CountryThr,2,FALSE),DefThrCountry),IFERROR(VLOOKUP($F11,CountryThr,2,FALSE),DefThrCountry)/$T11,1))) | Y11: =IF($B11="","",IF($D11=CashLabel,1,IF($U11>IFERROR(VLOOKUP($D11,LVTable,3,FALSE),DefThrAsset),IFERROR(VLOOKUP($D11,LVTable,3,FALSE),DefThrAsset)/$U11,1))) | Z11: =IF($B11="","",IF($D11=CashLabel,1,MIN($V11:$Y11))) | AA11: =IF($B11="","",$P11*$Z11) | AB11: =IF($B11="","",$P11-$AA11) | AC11: -0.1 | AD11: =IF($B11="","",$M11*(1+IF(ISNUMBER($AC11),$AC11,0))) | AE11: =IF($B11="","",$AD11*$O11) | AF11: =IF($B11="","",IF($D11=CashLabel,"",SUMIFS($AE$5:$AE$204,$B$5:$B$204,$B11,$D$5:$D$204,"<>"&CashLabel)/ConcDenomStr)) | AG11: =IF($B11="","",IF($D11=CashLabel,"",SUMIFS($AE$5:$AE$204,$E$5:$E$204,$E11,$D$5:$D$204,"<>"&CashLabel)/ConcDenomStr)) | AH11: =IF($B11="","",IF($D11=CashLabel,"",SUMIFS($AE$5:$AE$204,$F$5:$F$204,$F11,$D$5:$D$204,"<>"&CashLabel)/ConcDenomStr)) | AI11: =IF($B11="","",IF($D11=CashLabel,"",SUMIFS($AE$5:$AE$204,$D$5:$D$204,$D11,$D$5:$D$204,"<>"&CashLabel)/ConcDenomStr)) | AJ11: =IF($B11="","",IF($D11=CashLabel,1,MIN(IF($AF11>ThrSingle,ThrSingle/$AF11,1),IF($AG11>ThrIssuer,ThrIssuer/$AG11,1),IF($AH11>IFERROR(VLOOKUP($F11,CountryThr,2,FALSE),DefThrCountry),IFERROR(VLOOKUP($F11,CountryThr,2,FALSE),DefThrCountry)/$AH11,1),IF($AI11>IFERROR(VLOOKUP($D11,LVTable,3,FALSE),DefThrAsset),IFERROR(VLOOKUP($D11,LVTable,3,FALSE),DefThrAsset)/$AI11,1)))) | AK11: =IF($B11="","",$AE11*$AJ11)
A12: =IF($B12="","",ROW()-4) | K12: =IF($B12="","",IF(ISNUMBER($J12),$J12,$I12)) | L12: =IF($B12="","",IFERROR(VLOOKUP($G12,FXRates,4,FALSE),1)) | M12: =IF($B12="","",$H12*$K12*$L12) | O12: =IF($B12="","",IF($D12=CashLabel,IF(ISNUMBER($N12),$N12,1),MIN(IF(ISNUMBER($N12),$N12,IFERROR(VLOOKUP($D12,LVTable,2,FALSE),0)),LVCap))) | P12: =IF($B12="","",$M12*$O12) | Q12: =IF($B12="","",IFERROR(VLOOKUP($G12,FXRates,5,FALSE),$G12)) | R12: =IF($B12="","",IF($D12=CashLabel,"",SUMIFS($P$5:$P$204,$B$5:$B$204,$B12,$D$5:$D$204,"<>"&CashLabel)/ConcDenom)) | S12: =IF($B12="","",IF($D12=CashLabel,"",SUMIFS($P$5:$P$204,$E$5:$E$204,$E12,$D$5:$D$204,"<>"&CashLabel)/ConcDenom)) | T12: =IF($B12="","",IF($D12=CashLabel,"",SUMIFS($P$5:$P$204,$F$5:$F$204,$F12,$D$5:$D$204,"<>"&CashLabel)/ConcDenom)) | U12: =IF($B12="","",IF($D12=CashLabel,"",SUMIFS($P$5:$P$204,$D$5:$D$204,$D12,$D$5:$D$204,"<>"&CashLabel)/ConcDenom)) | V12: =IF($B12="","",IF($D12=CashLabel,1,IF($R12>ThrSingle,ThrSingle/$R12,1))) | W12: =IF($B12="","",IF($D12=CashLabel,1,IF($S12>ThrIssuer,ThrIssuer/$S12,1))) | X12: =IF($B12="","",IF($D12=CashLabel,1,IF($T12>IFERROR(VLOOKUP($F12,CountryThr,2,FALSE),DefThrCountry),IFERROR(VLOOKUP($F12,CountryThr,2,FALSE),DefThrCountry)/$T12,1))) | Y12: =IF($B12="","",IF($D12=CashLabel,1,IF($U12>IFERROR(VLOOKUP($D12,LVTable,3,FALSE),DefThrAsset),IFERROR(VLOOKUP($D12,LVTable,3,FALSE),DefThrAsset)/$U12,1))) | Z12: =IF($B12="","",IF($D12=CashLabel,1,MIN($V12:$Y12))) | AA12: =IF($B12="","",$P12*$Z12) | AB12: =IF($B12="","",$P12-$AA12) | AD12: =IF($B12="","",$M12*(1+IF(ISNUMBER($AC12),$AC12,0))) | AE12: =IF($B12="","",$AD12*$O12) | AF12: =IF($B12="","",IF($D12=CashLabel,"",SUMIFS($AE$5:$AE$204,$B$5:$B$204,$B12,$D$5:$D$204,"<>"&CashLabel)/ConcDenomStr)) | AG12: =IF($B12="","",IF($D12=CashLabel,"",SUMIFS($AE$5:$AE$204,$E$5:$E$204,$E12,$D$5:$D$204,"<>"&CashLabel)/ConcDenomStr)) | AH12: =IF($B12="","",IF($D12=CashLabel,"",SUMIFS($AE$5:$AE$204,$F$5:$F$204,$F12,$D$5:$D$204,"<>"&CashLabel)/ConcDenomStr)) | AI12: =IF($B12="","",IF($D12=CashLabel,"",SUMIFS($AE$5:$AE$204,$D$5:$D$204,$D12,$D$5:$D$204,"<>"&CashLabel)/ConcDenomStr)) | AJ12: =IF($B12="","",IF($D12=CashLabel,1,MIN(IF($AF12>ThrSingle,ThrSingle/$AF12,1),IF($AG12>ThrIssuer,ThrIssuer/$AG12,1),IF($AH12>IFERROR(VLOOKUP($F12,CountryThr,2,FALSE),DefThrCountry),IFERROR(VLOOKUP($F12,CountryThr,2,FALSE),DefThrCountry)/$AH12,1),IF($AI12>IFERROR(VLOOKUP($D12,LVTable,3,FALSE),DefThrAsset),IFERROR(VLOOKUP($D12,LVTable,3,FALSE),DefThrAsset)/$AI12,1)))) | AK12: =IF($B12="","",$AE12*$AJ12)
A13: =IF($B13="","",ROW()-4) | K13: =IF($B13="","",IF(ISNUMBER($J13),$J13,$I13)) | L13: =IF($B13="","",IFERROR(VLOOKUP($G13,FXRates,4,FALSE),1)) | M13: =IF($B13="","",$H13*$K13*$L13) | O13: =IF($B13="","",IF($D13=CashLabel,IF(ISNUMBER($N13),$N13,1),MIN(IF(ISNUMBER($N13),$N13,IFERROR(VLOOKUP($D13,LVTable,2,FALSE),0)),LVCap))) | P13: =IF($B13="","",$M13*$O13) | Q13: =IF($B13="","",IFERROR(VLOOKUP($G13,FXRates,5,FALSE),$G13)) | R13: =IF($B13="","",IF($D13=CashLabel,"",SUMIFS($P$5:$P$204,$B$5:$B$204,$B13,$D$5:$D$204,"<>"&CashLabel)/ConcDenom)) | S13: =IF($B13="","",IF($D13=CashLabel,"",SUMIFS($P$5:$P$204,$E$5:$E$204,$E13,$D$5:$D$204,"<>"&CashLabel)/ConcDenom)) | T13: =IF($B13="","",IF($D13=CashLabel,"",SUMIFS($P$5:$P$204,$F$5:$F$204,$F13,$D$5:$D$204,"<>"&CashLabel)/ConcDenom)) | U13: =IF($B13="","",IF($D13=CashLabel,"",SUMIFS($P$5:$P$204,$D$5:$D$204,$D13,$D$5:$D$204,"<>"&CashLabel)/ConcDenom)) | V13: =IF($B13="","",IF($D13=CashLabel,1,IF($R13>ThrSingle,ThrSingle/$R13,1))) | W13: =IF($B13="","",IF($D13=CashLabel,1,IF($S13>ThrIssuer,ThrIssuer/$S13,1))) | X13: =IF($B13="","",IF($D13=CashLabel,1,IF($T13>IFERROR(VLOOKUP($F13,CountryThr,2,FALSE),DefThrCountry),IFERROR(VLOOKUP($F13,CountryThr,2,FALSE),DefThrCountry)/$T13,1))) | Y13: =IF($B13="","",IF($D13=CashLabel,1,IF($U13>IFERROR(VLOOKUP($D13,LVTable,3,FALSE),DefThrAsset),IFERROR(VLOOKUP($D13,LVTable,3,FALSE),DefThrAsset)/$U13,1))) | Z13: =IF($B13="","",IF($D13=CashLabel,1,MIN($V13:$Y13))) | AA13: =IF($B13="","",$P13*$Z13) | AB13: =IF($B13="","",$P13-$AA13) | AD13: =IF($B13="","",$M13*(1+IF(ISNUMBER($AC13),$AC13,0))) | AE13: =IF($B13="","",$AD13*$O13) | AF13: =IF($B13="","",IF($D13=CashLabel,"",SUMIFS($AE$5:$AE$204,$B$5:$B$204,$B13,$D$5:$D$204,"<>"&CashLabel)/ConcDenomStr)) | AG13: =IF($B13="","",IF($D13=CashLabel,"",SUMIFS($AE$5:$AE$204,$E$5:$E$204,$E13,$D$5:$D$204,"<>"&CashLabel)/ConcDenomStr)) | AH13: =IF($B13="","",IF($D13=CashLabel,"",SUMIFS($AE$5:$AE$204,$F$5:$F$204,$F13,$D$5:$D$204,"<>"&CashLabel)/ConcDenomStr)) | AI13: =IF($B13="","",IF($D13=CashLabel,"",SUMIFS($AE$5:$AE$204,$D$5:$D$204,$D13,$D$5:$D$204,"<>"&CashLabel)/ConcDenomStr)) | AJ13: =IF($B13="","",IF($D13=CashLabel,1,MIN(IF($AF13>ThrSingle,ThrSingle/$AF13,1),IF($AG13>ThrIssuer,ThrIssuer/$AG13,1),IF($AH13>IFERROR(VLOOKUP($F13,CountryThr,2,FALSE),DefThrCountry),IFERROR(VLOOKUP($F13,CountryThr,2,FALSE),DefThrCountry)/$AH13,1),IF($AI13>IFERROR(VLOOKUP($D13,LVTable,3,FALSE),DefThrAsset),IFERROR(VLOOKUP($D13,LVTable,3,FALSE),DefThrAsset)/$AI13,1)))) | AK13: =IF($B13="","",$AE13*$AJ13)
A14: =IF($B14="","",ROW()-4) | K14: =IF($B14="","",IF(ISNUMBER($J14),$J14,$I14)) | L14: =IF($B14="","",IFERROR(VLOOKUP($G14,FXRates,4,FALSE),1)) | M14: =IF($B14="","",$H14*$K14*$L14) | O14: =IF($B14="","",IF($D14=CashLabel,IF(ISNUMBER($N14),$N14,1),MIN(IF(ISNUMBER($N14),$N14,IFERROR(VLOOKUP($D14,LVTable,2,FALSE),0)),LVCap))) | P14: =IF($B14="","",$M14*$O14) | Q14: =IF($B14="","",IFERROR(VLOOKUP($G14,FXRates,5,FALSE),$G14)) | R14: =IF($B14="","",IF($D14=CashLabel,"",SUMIFS($P$5:$P$204,$B$5:$B$204,$B14,$D$5:$D$204,"<>"&CashLabel)/ConcDenom)) | S14: =IF($B14="","",IF($D14=CashLabel,"",SUMIFS($P$5:$P$204,$E$5:$E$204,$E14,$D$5:$D$204,"<>"&CashLabel)/ConcDenom)) | T14: =IF($B14="","",IF($D14=CashLabel,"",SUMIFS($P$5:$P$204,$F$5:$F$204,$F14,$D$5:$D$204,"<>"&CashLabel)/ConcDenom)) | U14: =IF($B14="","",IF($D14=CashLabel,"",SUMIFS($P$5:$P$204,$D$5:$D$204,$D14,$D$5:$D$204,"<>"&CashLabel)/ConcDenom)) | V14: =IF($B14="","",IF($D14=CashLabel,1,IF($R14>ThrSingle,ThrSingle/$R14,1))) | W14: =IF($B14="","",IF($D14=CashLabel,1,IF($S14>ThrIssuer,ThrIssuer/$S14,1))) | X14: =IF($B14="","",IF($D14=CashLabel,1,IF($T14>IFERROR(VLOOKUP($F14,CountryThr,2,FALSE),DefThrCountry),IFERROR(VLOOKUP($F14,CountryThr,2,FALSE),DefThrCountry)/$T14,1))) | Y14: =IF($B14="","",IF($D14=CashLabel,1,IF($U14>IFERROR(VLOOKUP($D14,LVTable,3,FALSE),DefThrAsset),IFERROR(VLOOKUP($D14,LVTable,3,FALSE),DefThrAsset)/$U14,1))) | Z14: =IF($B14="","",IF($D14=CashLabel,1,MIN($V14:$Y14))) | AA14: =IF($B14="","",$P14*$Z14) | AB14: =IF($B14="","",$P14-$AA14) | AD14: =IF($B14="","",$M14*(1+IF(ISNUMBER($AC14),$AC14,0))) | AE14: =IF($B14="","",$AD14*$O14) | AF14: =IF($B14="","",IF($D14=CashLabel,"",SUMIFS($AE$5:$AE$204,$B$5:$B$204,$B14,$D$5:$D$204,"<>"&CashLabel)/ConcDenomStr)) | AG14: =IF($B14="","",IF($D14=CashLabel,"",SUMIFS($AE$5:$AE$204,$E$5:$E$204,$E14,$D$5:$D$204,"<>"&CashLabel)/ConcDenomStr)) | AH14: =IF($B14="","",IF($D14=CashLabel,"",SUMIFS($AE$5:$AE$204,$F$5:$F$204,$F14,$D$5:$D$204,"<>"&CashLabel)/ConcDenomStr)) | AI14: =IF($B14="","",IF($D14=CashLabel,"",SUMIFS($AE$5:$AE$204,$D$5:$D$204,$D14,$D$5:$D$204,"<>"&CashLabel)/ConcDenomStr)) | AJ14: =IF($B14="","",IF($D14=CashLabel,1,MIN(IF($AF14>ThrSingle,ThrSingle/$AF14,1),IF($AG14>ThrIssuer,ThrIssuer/$AG14,1),IF($AH14>IFERROR(VLOOKUP($F14,CountryThr,2,FALSE),DefThrCountry),IFERROR(VLOOKUP($F14,CountryThr,2,FALSE),DefThrCountry)/$AH14,1),IF($AI14>IFERROR(VLOOKUP($D14,LVTable,3,FALSE),DefThrAsset),IFERROR(VLOOKUP($D14,LVTable,3,FALSE),DefThrAsset)/$AI14,1)))) | AK14: =IF($B14="","",$AE14*$AJ14)
A15: =IF($B15="","",ROW()-4) | K15: =IF($B15="","",IF(ISNUMBER($J15),$J15,$I15)) | L15: =IF($B15="","",IFERROR(VLOOKUP($G15,FXRates,4,FALSE),1)) | M15: =IF($B15="","",$H15*$K15*$L15) | O15: =IF($B15="","",IF($D15=CashLabel,IF(ISNUMBER($N15),$N15,1),MIN(IF(ISNUMBER($N15),$N15,IFERROR(VLOOKUP($D15,LVTable,2,FALSE),0)),LVCap))) | P15: =IF($B15="","",$M15*$O15) | Q15: =IF($B15="","",IFERROR(VLOOKUP($G15,FXRates,5,FALSE),$G15)) | R15: =IF($B15="","",IF($D15=CashLabel,"",SUMIFS($P$5:$P$204,$B$5:$B$204,$B15,$D$5:$D$204,"<>"&CashLabel)/ConcDenom)) | S15: =IF($B15="","",IF($D15=CashLabel,"",SUMIFS($P$5:$P$204,$E$5:$E$204,$E15,$D$5:$D$204,"<>"&CashLabel)/ConcDenom)) | T15: =IF($B15="","",IF($D15=CashLabel,"",SUMIFS($P$5:$P$204,$F$5:$F$204,$F15,$D$5:$D$204,"<>"&CashLabel)/ConcDenom)) | U15: =IF($B15="","",IF($D15=CashLabel,"",SUMIFS($P$5:$P$204,$D$5:$D$204,$D15,$D$5:$D$204,"<>"&CashLabel)/ConcDenom)) | V15: =IF($B15="","",IF($D15=CashLabel,1,IF($R15>ThrSingle,ThrSingle/$R15,1))) | W15: =IF($B15="","",IF($D15=CashLabel,1,IF($S15>ThrIssuer,ThrIssuer/$S15,1))) | X15: =IF($B15="","",IF($D15=CashLabel,1,IF($T15>IFERROR(VLOOKUP($F15,CountryThr,2,FALSE),DefThrCountry),IFERROR(VLOOKUP($F15,CountryThr,2,FALSE),DefThrCountry)/$T15,1))) | Y15: =IF($B15="","",IF($D15=CashLabel,1,IF($U15>IFERROR(VLOOKUP($D15,LVTable,3,FALSE),DefThrAsset),IFERROR(VLOOKUP($D15,LVTable,3,FALSE),DefThrAsset)/$U15,1))) | Z15: =IF($B15="","",IF($D15=CashLabel,1,MIN($V15:$Y15))) | AA15: =IF($B15="","",$P15*$Z15) | AB15: =IF($B15="","",$P15-$AA15) | AD15: =IF($B15="","",$M15*(1+IF(ISNUMBER($AC15),$AC15,0))) | AE15: =IF($B15="","",$AD15*$O15) | AF15: =IF($B15="","",IF($D15=CashLabel,"",SUMIFS($AE$5:$AE$204,$B$5:$B$204,$B15,$D$5:$D$204,"<>"&CashLabel)/ConcDenomStr)) | AG15: =IF($B15="","",IF($D15=CashLabel,"",SUMIFS($AE$5:$AE$204,$E$5:$E$204,$E15,$D$5:$D$204,"<>"&CashLabel)/ConcDenomStr)) | AH15: =IF($B15="","",IF($D15=CashLabel,"",SUMIFS($AE$5:$AE$204,$F$5:$F$204,$F15,$D$5:$D$204,"<>"&CashLabel)/ConcDenomStr)) | AI15: =IF($B15="","",IF($D15=CashLabel,"",SUMIFS($AE$5:$AE$204,$D$5:$D$204,$D15,$D$5:$D$204,"<>"&CashLabel)/ConcDenomStr)) | AJ15: =IF($B15="","",IF($D15=CashLabel,1,MIN(IF($AF15>ThrSingle,ThrSingle/$AF15,1),IF($AG15>ThrIssuer,ThrIssuer/$AG15,1),IF($AH15>IFERROR(VLOOKUP($F15,CountryThr,2,FALSE),DefThrCountry),IFERROR(VLOOKUP($F15,CountryThr,2,FALSE),DefThrCountry)/$AH15,1),IF($AI15>IFERROR(VLOOKUP($D15,LVTable,3,FALSE),DefThrAsset),IFERROR(VLOOKUP($D15,LVTable,3,FALSE),DefThrAsset)/$AI15,1)))) | AK15: =IF($B15="","",$AE15*$AJ15)
A16: =IF($B16="","",ROW()-4) | K16: =IF($B16="","",IF(ISNUMBER($J16),$J16,$I16)) | L16: =IF($B16="","",IFERROR(VLOOKUP($G16,FXRates,4,FALSE),1)) | M16: =IF($B16="","",$H16*$K16*$L16) | O16: =IF($B16="","",IF($D16=CashLabel,IF(ISNUMBER($N16),$N16,1),MIN(IF(ISNUMBER($N16),$N16,IFERROR(VLOOKUP($D16,LVTable,2,FALSE),0)),LVCap))) | P16: =IF($B16="","",$M16*$O16) | Q16: =IF($B16="","",IFERROR(VLOOKUP($G16,FXRates,5,FALSE),$G16)) | R16: =IF($B16="","",IF($D16=CashLabel,"",SUMIFS($P$5:$P$204,$B$5:$B$204,$B16,$D$5:$D$204,"<>"&CashLabel)/ConcDenom)) | S16: =IF($B16="","",IF($D16=CashLabel,"",SUMIFS($P$5:$P$204,$E$5:$E$204,$E16,$D$5:$D$204,"<>"&CashLabel)/ConcDenom)) | T16: =IF($B16="","",IF($D16=CashLabel,"",SUMIFS($P$5:$P$204,$F$5:$F$204,$F16,$D$5:$D$204,"<>"&CashLabel)/ConcDenom)) | U16: =IF($B16="","",IF($D16=CashLabel,"",SUMIFS($P$5:$P$204,$D$5:$D$204,$D16,$D$5:$D$204,"<>"&CashLabel)/ConcDenom)) | V16: =IF($B16="","",IF($D16=CashLabel,1,IF($R16>ThrSingle,ThrSingle/$R16,1))) | W16: =IF($B16="","",IF($D16=CashLabel,1,IF($S16>ThrIssuer,ThrIssuer/$S16,1))) | X16: =IF($B16="","",IF($D16=CashLabel,1,IF($T16>IFERROR(VLOOKUP($F16,CountryThr,2,FALSE),DefThrCountry),IFERROR(VLOOKUP($F16,CountryThr,2,FALSE),DefThrCountry)/$T16,1))) | Y16: =IF($B16="","",IF($D16=CashLabel,1,IF($U16>IFERROR(VLOOKUP($D16,LVTable,3,FALSE),DefThrAsset),IFERROR(VLOOKUP($D16,LVTable,3,FALSE),DefThrAsset)/$U16,1))) | Z16: =IF($B16="","",IF($D16=CashLabel,1,MIN($V16:$Y16))) | AA16: =IF($B16="","",$P16*$Z16) | AB16: =IF($B16="","",$P16-$AA16) | AD16: =IF($B16="","",$M16*(1+IF(ISNUMBER($AC16),$AC16,0))) | AE16: =IF($B16="","",$AD16*$O16) | AF16: =IF($B16="","",IF($D16=CashLabel,"",SUMIFS($AE$5:$AE$204,$B$5:$B$204,$B16,$D$5:$D$204,"<>"&CashLabel)/ConcDenomStr)) | AG16: =IF($B16="","",IF($D16=CashLabel,"",SUMIFS($AE$5:$AE$204,$E$5:$E$204,$E16,$D$5:$D$204,"<>"&CashLabel)/ConcDenomStr)) | AH16: =IF($B16="","",IF($D16=CashLabel,"",SUMIFS($AE$5:$AE$204,$F$5:$F$204,$F16,$D$5:$D$204,"<>"&CashLabel)/ConcDenomStr)) | AI16: =IF($B16="","",IF($D16=CashLabel,"",SUMIFS($AE$5:$AE$204,$D$5:$D$204,$D16,$D$5:$D$204,"<>"&CashLabel)/ConcDenomStr)) | AJ16: =IF($B16="","",IF($D16=CashLabel,1,MIN(IF($AF16>ThrSingle,ThrSingle/$AF16,1),IF($AG16>ThrIssuer,ThrIssuer/$AG16,1),IF($AH16>IFERROR(VLOOKUP($F16,CountryThr,2,FALSE),DefThrCountry),IFERROR(VLOOKUP($F16,CountryThr,2,FALSE),DefThrCountry)/$AH16,1),IF($AI16>IFERROR(VLOOKUP($D16,LVTable,3,FALSE),DefThrAsset),IFERROR(VLOOKUP($D16,LVTable,3,FALSE),DefThrAsset)/$AI16,1)))) | AK16: =IF($B16="","",$AE16*$AJ16)
A17: =IF($B17="","",ROW()-4) | K17: =IF($B17="","",IF(ISNUMBER($J17),$J17,$I17)) | L17: =IF($B17="","",IFERROR(VLOOKUP($G17,FXRates,4,FALSE),1)) | M17: =IF($B17="","",$H17*$K17*$L17) | O17: =IF($B17="","",IF($D17=CashLabel,IF(ISNUMBER($N17),$N17,1),MIN(IF(ISNUMBER($N17),$N17,IFERROR(VLOOKUP($D17,LVTable,2,FALSE),0)),LVCap))) | P17: =IF($B17="","",$M17*$O17) | Q17: =IF($B17="","",IFERROR(VLOOKUP($G17,FXRates,5,FALSE),$G17)) | R17: =IF($B17="","",IF($D17=CashLabel,"",SUMIFS($P$5:$P$204,$B$5:$B$204,$B17,$D$5:$D$204,"<>"&CashLabel)/ConcDenom)) | S17: =IF($B17="","",IF($D17=CashLabel,"",SUMIFS($P$5:$P$204,$E$5:$E$204,$E17,$D$5:$D$204,"<>"&CashLabel)/ConcDenom)) | T17: =IF($B17="","",IF($D17=CashLabel,"",SUMIFS($P$5:$P$204,$F$5:$F$204,$F17,$D$5:$D$204,"<>"&CashLabel)/ConcDenom)) | U17: =IF($B17="","",IF($D17=CashLabel,"",SUMIFS($P$5:$P$204,$D$5:$D$204,$D17,$D$5:$D$204,"<>"&CashLabel)/ConcDenom)) | V17: =IF($B17="","",IF($D17=CashLabel,1,IF($R17>ThrSingle,ThrSingle/$R17,1))) | W17: =IF($B17="","",IF($D17=CashLabel,1,IF($S17>ThrIssuer,ThrIssuer/$S17,1))) | X17: =IF($B17="","",IF($D17=CashLabel,1,IF($T17>IFERROR(VLOOKUP($F17,CountryThr,2,FALSE),DefThrCountry),IFERROR(VLOOKUP($F17,CountryThr,2,FALSE),DefThrCountry)/$T17,1))) | Y17: =IF($B17="","",IF($D17=CashLabel,1,IF($U17>IFERROR(VLOOKUP($D17,LVTable,3,FALSE),DefThrAsset),IFERROR(VLOOKUP($D17,LVTable,3,FALSE),DefThrAsset)/$U17,1))) | Z17: =IF($B17="","",IF($D17=CashLabel,1,MIN($V17:$Y17))) | AA17: =IF($B17="","",$P17*$Z17) | AB17: =IF($B17="","",$P17-$AA17) | AD17: =IF($B17="","",$M17*(1+IF(ISNUMBER($AC17),$AC17,0))) | AE17: =IF($B17="","",$AD17*$O17) | AF17: =IF($B17="","",IF($D17=CashLabel,"",SUMIFS($AE$5:$AE$204,$B$5:$B$204,$B17,$D$5:$D$204,"<>"&CashLabel)/ConcDenomStr)) | AG17: =IF($B17="","",IF($D17=CashLabel,"",SUMIFS($AE$5:$AE$204,$E$5:$E$204,$E17,$D$5:$D$204,"<>"&CashLabel)/ConcDenomStr)) | AH17: =IF($B17="","",IF($D17=CashLabel,"",SUMIFS($AE$5:$AE$204,$F$5:$F$204,$F17,$D$5:$D$204,"<>"&CashLabel)/ConcDenomStr)) | AI17: =IF($B17="","",IF($D17=CashLabel,"",SUMIFS($AE$5:$AE$204,$D$5:$D$204,$D17,$D$5:$D$204,"<>"&CashLabel)/ConcDenomStr)) | AJ17: =IF($B17="","",IF($D17=CashLabel,1,MIN(IF($AF17>ThrSingle,ThrSingle/$AF17,1),IF($AG17>ThrIssuer,ThrIssuer/$AG17,1),IF($AH17>IFERROR(VLOOKUP($F17,CountryThr,2,FALSE),DefThrCountry),IFERROR(VLOOKUP($F17,CountryThr,2,FALSE),DefThrCountry)/$AH17,1),IF($AI17>IFERROR(VLOOKUP($D17,LVTable,3,FALSE),DefThrAsset),IFERROR(VLOOKUP($D17,LVTable,3,FALSE),DefThrAsset)/$AI17,1)))) | AK17: =IF($B17="","",$AE17*$AJ17)
A18: =IF($B18="","",ROW()-4) | K18: =IF($B18="","",IF(ISNUMBER($J18),$J18,$I18)) | L18: =IF($B18="","",IFERROR(VLOOKUP($G18,FXRates,4,FALSE),1)) | M18: =IF($B18="","",$H18*$K18*$L18) | O18: =IF($B18="","",IF($D18=CashLabel,IF(ISNUMBER($N18),$N18,1),MIN(IF(ISNUMBER($N18),$N18,IFERROR(VLOOKUP($D18,LVTable,2,FALSE),0)),LVCap))) | P18: =IF($B18="","",$M18*$O18) | Q18: =IF($B18="","",IFERROR(VLOOKUP($G18,FXRates,5,FALSE),$G18)) | R18: =IF($B18="","",IF($D18=CashLabel,"",SUMIFS($P$5:$P$204,$B$5:$B$204,$B18,$D$5:$D$204,"<>"&CashLabel)/ConcDenom)) | S18: =IF($B18="","",IF($D18=CashLabel,"",SUMIFS($P$5:$P$204,$E$5:$E$204,$E18,$D$5:$D$204,"<>"&CashLabel)/ConcDenom)) | T18: =IF($B18="","",IF($D18=CashLabel,"",SUMIFS($P$5:$P$204,$F$5:$F$204,$F18,$D$5:$D$204,"<>"&CashLabel)/ConcDenom)) | U18: =IF($B18="","",IF($D18=CashLabel,"",SUMIFS($P$5:$P$204,$D$5:$D$204,$D18,$D$5:$D$204,"<>"&CashLabel)/ConcDenom)) | V18: =IF($B18="","",IF($D18=CashLabel,1,IF($R18>ThrSingle,ThrSingle/$R18,1))) | W18: =IF($B18="","",IF($D18=CashLabel,1,IF($S18>ThrIssuer,ThrIssuer/$S18,1))) | X18: =IF($B18="","",IF($D18=CashLabel,1,IF($T18>IFERROR(VLOOKUP($F18,CountryThr,2,FALSE),DefThrCountry),IFERROR(VLOOKUP($F18,CountryThr,2,FALSE),DefThrCountry)/$T18,1))) | Y18: =IF($B18="","",IF($D18=CashLabel,1,IF($U18>IFERROR(VLOOKUP($D18,LVTable,3,FALSE),DefThrAsset),IFERROR(VLOOKUP($D18,LVTable,3,FALSE),DefThrAsset)/$U18,1))) | Z18: =IF($B18="","",IF($D18=CashLabel,1,MIN($V18:$Y18))) | AA18: =IF($B18="","",$P18*$Z18) | AB18: =IF($B18="","",$P18-$AA18) | AD18: =IF($B18="","",$M18*(1+IF(ISNUMBER($AC18),$AC18,0))) | AE18: =IF($B18="","",$AD18*$O18) | AF18: =IF($B18="","",IF($D18=CashLabel,"",SUMIFS($AE$5:$AE$204,$B$5:$B$204,$B18,$D$5:$D$204,"<>"&CashLabel)/ConcDenomStr)) | AG18: =IF($B18="","",IF($D18=CashLabel,"",SUMIFS($AE$5:$AE$204,$E$5:$E$204,$E18,$D$5:$D$204,"<>"&CashLabel)/ConcDenomStr)) | AH18: =IF($B18="","",IF($D18=CashLabel,"",SUMIFS($AE$5:$AE$204,$F$5:$F$204,$F18,$D$5:$D$204,"<>"&CashLabel)/ConcDenomStr)) | AI18: =IF($B18="","",IF($D18=CashLabel,"",SUMIFS($AE$5:$AE$204,$D$5:$D$204,$D18,$D$5:$D$204,"<>"&CashLabel)/ConcDenomStr)) | AJ18: =IF($B18="","",IF($D18=CashLabel,1,MIN(IF($AF18>ThrSingle,ThrSingle/$AF18,1),IF($AG18>ThrIssuer,ThrIssuer/$AG18,1),IF($AH18>IFERROR(VLOOKUP($F18,CountryThr,2,FALSE),DefThrCountry),IFERROR(VLOOKUP($F18,CountryThr,2,FALSE),DefThrCountry)/$AH18,1),IF($AI18>IFERROR(VLOOKUP($D18,LVTable,3,FALSE),DefThrAsset),IFERROR(VLOOKUP($D18,LVTable,3,FALSE),DefThrAsset)/$AI18,1)))) | AK18: =IF($B18="","",$AE18*$AJ18)
A19: =IF($B19="","",ROW()-4) | K19: =IF($B19="","",IF(ISNUMBER($J19),$J19,$I19)) | L19: =IF($B19="","",IFERROR(VLOOKUP($G19,FXRates,4,FALSE),1)) | M19: =IF($B19="","",$H19*$K19*$L19) | O19: =IF($B19="","",IF($D19=CashLabel,IF(ISNUMBER($N19),$N19,1),MIN(IF(ISNUMBER($N19),$N19,IFERROR(VLOOKUP($D19,LVTable,2,FALSE),0)),LVCap))) | P19: =IF($B19="","",$M19*$O19) | Q19: =IF($B19="","",IFERROR(VLOOKUP($G19,FXRates,5,FALSE),$G19)) | R19: =IF($B19="","",IF($D19=CashLabel,"",SUMIFS($P$5:$P$204,$B$5:$B$204,$B19,$D$5:$D$204,"<>"&CashLabel)/ConcDenom)) | S19: =IF($B19="","",IF($D19=CashLabel,"",SUMIFS($P$5:$P$204,$E$5:$E$204,$E19,$D$5:$D$204,"<>"&CashLabel)/ConcDenom)) | T19: =IF($B19="","",IF($D19=CashLabel,"",SUMIFS($P$5:$P$204,$F$5:$F$204,$F19,$D$5:$D$204,"<>"&CashLabel)/ConcDenom)) | U19: =IF($B19="","",IF($D19=CashLabel,"",SUMIFS($P$5:$P$204,$D$5:$D$204,$D19,$D$5:$D$204,"<>"&CashLabel)/ConcDenom)) | V19: =IF($B19="","",IF($D19=CashLabel,1,IF($R19>ThrSingle,ThrSingle/$R19,1))) | W19: =IF($B19="","",IF($D19=CashLabel,1,IF($S19>ThrIssuer,ThrIssuer/$S19,1))) | X19: =IF($B19="","",IF($D19=CashLabel,1,IF($T19>IFERROR(VLOOKUP($F19,CountryThr,2,FALSE),DefThrCountry),IFERROR(VLOOKUP($F19,CountryThr,2,FALSE),DefThrCountry)/$T19,1))) | Y19: =IF($B19="","",IF($D19=CashLabel,1,IF($U19>IFERROR(VLOOKUP($D19,LVTable,3,FALSE),DefThrAsset),IFERROR(VLOOKUP($D19,LVTable,3,FALSE),DefThrAsset)/$U19,1))) | Z19: =IF($B19="","",IF($D19=CashLabel,1,MIN($V19:$Y19))) | AA19: =IF($B19="","",$P19*$Z19) | AB19: =IF($B19="","",$P19-$AA19) | AD19: =IF($B19="","",$M19*(1+IF(ISNUMBER($AC19),$AC19,0))) | AE19: =IF($B19="","",$AD19*$O19) | AF19: =IF($B19="","",IF($D19=CashLabel,"",SUMIFS($AE$5:$AE$204,$B$5:$B$204,$B19,$D$5:$D$204,"<>"&CashLabel)/ConcDenomStr)) | AG19: =IF($B19="","",IF($D19=CashLabel,"",SUMIFS($AE$5:$AE$204,$E$5:$E$204,$E19,$D$5:$D$204,"<>"&CashLabel)/ConcDenomStr)) | AH19: =IF($B19="","",IF($D19=CashLabel,"",SUMIFS($AE$5:$AE$204,$F$5:$F$204,$F19,$D$5:$D$204,"<>"&CashLabel)/ConcDenomStr)) | AI19: =IF($B19="","",IF($D19=CashLabel,"",SUMIFS($AE$5:$AE$204,$D$5:$D$204,$D19,$D$5:$D$204,"<>"&CashLabel)/ConcDenomStr)) | AJ19: =IF($B19="","",IF($D19=CashLabel,1,MIN(IF($AF19>ThrSingle,ThrSingle/$AF19,1),IF($AG19>ThrIssuer,ThrIssuer/$AG19,1),IF($AH19>IFERROR(VLOOKUP($F19,CountryThr,2,FALSE),DefThrCountry),IFERROR(VLOOKUP($F19,CountryThr,2,FALSE),DefThrCountry)/$AH19,1),IF($AI19>IFERROR(VLOOKUP($D19,LVTable,3,FALSE),DefThrAsset),IFERROR(VLOOKUP($D19,LVTable,3,FALSE),DefThrAsset)/$AI19,1)))) | AK19: =IF($B19="","",$AE19*$AJ19)
A20: =IF($B20="","",ROW()-4) | K20: =IF($B20="","",IF(ISNUMBER($J20),$J20,$I20)) | L20: =IF($B20="","",IFERROR(VLOOKUP($G20,FXRates,4,FALSE),1)) | M20: =IF($B20="","",$H20*$K20*$L20) | O20: =IF($B20="","",IF($D20=CashLabel,IF(ISNUMBER($N20),$N20,1),MIN(IF(ISNUMBER($N20),$N20,IFERROR(VLOOKUP($D20,LVTable,2,FALSE),0)),LVCap))) | P20: =IF($B20="","",$M20*$O20) | Q20: =IF($B20="","",IFERROR(VLOOKUP($G20,FXRates,5,FALSE),$G20)) | R20: =IF($B20="","",IF($D20=CashLabel,"",SUMIFS($P$5:$P$204,$B$5:$B$204,$B20,$D$5:$D$204,"<>"&CashLabel)/ConcDenom)) | S20: =IF($B20="","",IF($D20=CashLabel,"",SUMIFS($P$5:$P$204,$E$5:$E$204,$E20,$D$5:$D$204,"<>"&CashLabel)/ConcDenom)) | T20: =IF($B20="","",IF($D20=CashLabel,"",SUMIFS($P$5:$P$204,$F$5:$F$204,$F20,$D$5:$D$204,"<>"&CashLabel)/ConcDenom)) | U20: =IF($B20="","",IF($D20=CashLabel,"",SUMIFS($P$5:$P$204,$D$5:$D$204,$D20,$D$5:$D$204,"<>"&CashLabel)/ConcDenom)) | V20: =IF($B20="","",IF($D20=CashLabel,1,IF($R20>ThrSingle,ThrSingle/$R20,1))) | W20: =IF($B20="","",IF($D20=CashLabel,1,IF($S20>ThrIssuer,ThrIssuer/$S20,1))) | X20: =IF($B20="","",IF($D20=CashLabel,1,IF($T20>IFERROR(VLOOKUP($F20,CountryThr,2,FALSE),DefThrCountry),IFERROR(VLOOKUP($F20,CountryThr,2,FALSE),DefThrCountry)/$T20,1))) | Y20: =IF($B20="","",IF($D20=CashLabel,1,IF($U20>IFERROR(VLOOKUP($D20,LVTable,3,FALSE),DefThrAsset),IFERROR(VLOOKUP($D20,LVTable,3,FALSE),DefThrAsset)/$U20,1))) | Z20: =IF($B20="","",IF($D20=CashLabel,1,MIN($V20:$Y20))) | AA20: =IF($B20="","",$P20*$Z20) | AB20: =IF($B20="","",$P20-$AA20) | AD20: =IF($B20="","",$M20*(1+IF(ISNUMBER($AC20),$AC20,0))) | AE20: =IF($B20="","",$AD20*$O20) | AF20: =IF($B20="","",IF($D20=CashLabel,"",SUMIFS($AE$5:$AE$204,$B$5:$B$204,$B20,$D$5:$D$204,"<>"&CashLabel)/ConcDenomStr)) | AG20: =IF($B20="","",IF($D20=CashLabel,"",SUMIFS($AE$5:$AE$204,$E$5:$E$204,$E20,$D$5:$D$204,"<>"&CashLabel)/ConcDenomStr)) | AH20: =IF($B20="","",IF($D20=CashLabel,"",SUMIFS($AE$5:$AE$204,$F$5:$F$204,$F20,$D$5:$D$204,"<>"&CashLabel)/ConcDenomStr)) | AI20: =IF($B20="","",IF($D20=CashLabel,"",SUMIFS($AE$5:$AE$204,$D$5:$D$204,$D20,$D$5:$D$204,"<>"&CashLabel)/ConcDenomStr)) | AJ20: =IF($B20="","",IF($D20=CashLabel,1,MIN(IF($AF20>ThrSingle,ThrSingle/$AF20,1),IF($AG20>ThrIssuer,ThrIssuer/$AG20,1),IF($AH20>IFERROR(VLOOKUP($F20,CountryThr,2,FALSE),DefThrCountry),IFERROR(VLOOKUP($F20,CountryThr,2,FALSE),DefThrCountry)/$AH20,1),IF($AI20>IFERROR(VLOOKUP($D20,LVTable,3,FALSE),DefThrAsset),IFERROR(VLOOKUP($D20,LVTable,3,FALSE),DefThrAsset)/$AI20,1)))) | AK20: =IF($B20="","",$AE20*$AJ20)
A21: =IF($B21="","",ROW()-4) | K21: =IF($B21="","",IF(ISNUMBER($J21),$J21,$I21)) | L21: =IF($B21="","",IFERROR(VLOOKUP($G21,FXRates,4,FALSE),1)) | M21: =IF($B21="","",$H21*$K21*$L21) | O21: =IF($B21="","",IF($D21=CashLabel,IF(ISNUMBER($N21),$N21,1),MIN(IF(ISNUMBER($N21),$N21,IFERROR(VLOOKUP($D21,LVTable,2,FALSE),0)),LVCap))) | P21: =IF($B21="","",$M21*$O21) | Q21: =IF($B21="","",IFERROR(VLOOKUP($G21,FXRates,5,FALSE),$G21)) | R21: =IF($B21="","",IF($D21=CashLabel,"",SUMIFS($P$5:$P$204,$B$5:$B$204,$B21,$D$5:$D$204,"<>"&CashLabel)/ConcDenom)) | S21: =IF($B21="","",IF($D21=CashLabel,"",SUMIFS($P$5:$P$204,$E$5:$E$204,$E21,$D$5:$D$204,"<>"&CashLabel)/ConcDenom)) | T21: =IF($B21="","",IF($D21=CashLabel,"",SUMIFS($P$5:$P$204,$F$5:$F$204,$F21,$D$5:$D$204,"<>"&CashLabel)/ConcDenom)) | U21: =IF($B21="","",IF($D21=CashLabel,"",SUMIFS($P$5:$P$204,$D$5:$D$204,$D21,$D$5:$D$204,"<>"&CashLabel)/ConcDenom)) | V21: =IF($B21="","",IF($D21=CashLabel,1,IF($R21>ThrSingle,ThrSingle/$R21,1))) | W21: =IF($B21="","",IF($D21=CashLabel,1,IF($S21>ThrIssuer,ThrIssuer/$S21,1))) | X21: =IF($B21="","",IF($D21=CashLabel,1,IF($T21>IFERROR(VLOOKUP($F21,CountryThr,2,FALSE),DefThrCountry),IFERROR(VLOOKUP($F21,CountryThr,2,FALSE),DefThrCountry)/$T21,1))) | Y21: =IF($B21="","",IF($D21=CashLabel,1,IF($U21>IFERROR(VLOOKUP($D21,LVTable,3,FALSE),DefThrAsset),IFERROR(VLOOKUP($D21,LVTable,3,FALSE),DefThrAsset)/$U21,1))) | Z21: =IF($B21="","",IF($D21=CashLabel,1,MIN($V21:$Y21))) | AA21: =IF($B21="","",$P21*$Z21) | AB21: =IF($B21="","",$P21-$AA21) | AD21: =IF($B21="","",$M21*(1+IF(ISNUMBER($AC21),$AC21,0))) | AE21: =IF($B21="","",$AD21*$O21) | AF21: =IF($B21="","",IF($D21=CashLabel,"",SUMIFS($AE$5:$AE$204,$B$5:$B$204,$B21,$D$5:$D$204,"<>"&CashLabel)/ConcDenomStr)) | AG21: =IF($B21="","",IF($D21=CashLabel,"",SUMIFS($AE$5:$AE$204,$E$5:$E$204,$E21,$D$5:$D$204,"<>"&CashLabel)/ConcDenomStr)) | AH21: =IF($B21="","",IF($D21=CashLabel,"",SUMIFS($AE$5:$AE$204,$F$5:$F$204,$F21,$D$5:$D$204,"<>"&CashLabel)/ConcDenomStr)) | AI21: =IF($B21="","",IF($D21=CashLabel,"",SUMIFS($AE$5:$AE$204,$D$5:$D$204,$D21,$D$5:$D$204,"<>"&CashLabel)/ConcDenomStr)) | AJ21: =IF($B21="","",IF($D21=CashLabel,1,MIN(IF($AF21>ThrSingle,ThrSingle/$AF21,1),IF($AG21>ThrIssuer,ThrIssuer/$AG21,1),IF($AH21>IFERROR(VLOOKUP($F21,CountryThr,2,FALSE),DefThrCountry),IFERROR(VLOOKUP($F21,CountryThr,2,FALSE),DefThrCountry)/$AH21,1),IF($AI21>IFERROR(VLOOKUP($D21,LVTable,3,FALSE),DefThrAsset),IFERROR(VLOOKUP($D21,LVTable,3,FALSE),DefThrAsset)/$AI21,1)))) | AK21: =IF($B21="","",$AE21*$AJ21)
A22: =IF($B22="","",ROW()-4) | K22: =IF($B22="","",IF(ISNUMBER($J22),$J22,$I22)) | L22: =IF($B22="","",IFERROR(VLOOKUP($G22,FXRates,4,FALSE),1)) | M22: =IF($B22="","",$H22*$K22*$L22) | O22: =IF($B22="","",IF($D22=CashLabel,IF(ISNUMBER($N22),$N22,1),MIN(IF(ISNUMBER($N22),$N22,IFERROR(VLOOKUP($D22,LVTable,2,FALSE),0)),LVCap))) | P22: =IF($B22="","",$M22*$O22) | Q22: =IF($B22="","",IFERROR(VLOOKUP($G22,FXRates,5,FALSE),$G22)) | R22: =IF($B22="","",IF($D22=CashLabel,"",SUMIFS($P$5:$P$204,$B$5:$B$204,$B22,$D$5:$D$204,"<>"&CashLabel)/ConcDenom)) | S22: =IF($B22="","",IF($D22=CashLabel,"",SUMIFS($P$5:$P$204,$E$5:$E$204,$E22,$D$5:$D$204,"<>"&CashLabel)/ConcDenom)) | T22: =IF($B22="","",IF($D22=CashLabel,"",SUMIFS($P$5:$P$204,$F$5:$F$204,$F22,$D$5:$D$204,"<>"&CashLabel)/ConcDenom)) | U22: =IF($B22="","",IF($D22=CashLabel,"",SUMIFS($P$5:$P$204,$D$5:$D$204,$D22,$D$5:$D$204,"<>"&CashLabel)/ConcDenom)) | V22: =IF($B22="","",IF($D22=CashLabel,1,IF($R22>ThrSingle,ThrSingle/$R22,1))) | W22: =IF($B22="","",IF($D22=CashLabel,1,IF($S22>ThrIssuer,ThrIssuer/$S22,1))) | X22: =IF($B22="","",IF($D22=CashLabel,1,IF($T22>IFERROR(VLOOKUP($F22,CountryThr,2,FALSE),DefThrCountry),IFERROR(VLOOKUP($F22,CountryThr,2,FALSE),DefThrCountry)/$T22,1))) | Y22: =IF($B22="","",IF($D22=CashLabel,1,IF($U22>IFERROR(VLOOKUP($D22,LVTable,3,FALSE),DefThrAsset),IFERROR(VLOOKUP($D22,LVTable,3,FALSE),DefThrAsset)/$U22,1))) | Z22: =IF($B22="","",IF($D22=CashLabel,1,MIN($V22:$Y22))) | AA22: =IF($B22="","",$P22*$Z22) | AB22: =IF($B22="","",$P22-$AA22) | AD22: =IF($B22="","",$M22*(1+IF(ISNUMBER($AC22),$AC22,0))) | AE22: =IF($B22="","",$AD22*$O22) | AF22: =IF($B22="","",IF($D22=CashLabel,"",SUMIFS($AE$5:$AE$204,$B$5:$B$204,$B22,$D$5:$D$204,"<>"&CashLabel)/ConcDenomStr)) | AG22: =IF($B22="","",IF($D22=CashLabel,"",SUMIFS($AE$5:$AE$204,$E$5:$E$204,$E22,$D$5:$D$204,"<>"&CashLabel)/ConcDenomStr)) | AH22: =IF($B22="","",IF($D22=CashLabel,"",SUMIFS($AE$5:$AE$204,$F$5:$F$204,$F22,$D$5:$D$204,"<>"&CashLabel)/ConcDenomStr)) | AI22: =IF($B22="","",IF($D22=CashLabel,"",SUMIFS($AE$5:$AE$204,$D$5:$D$204,$D22,$D$5:$D$204,"<>"&CashLabel)/ConcDenomStr)) | AJ22: =IF($B22="","",IF($D22=CashLabel,1,MIN(IF($AF22>ThrSingle,ThrSingle/$AF22,1),IF($AG22>ThrIssuer,ThrIssuer/$AG22,1),IF($AH22>IFERROR(VLOOKUP($F22,CountryThr,2,FALSE),DefThrCountry),IFERROR(VLOOKUP($F22,CountryThr,2,FALSE),DefThrCountry)/$AH22,1),IF($AI22>IFERROR(VLOOKUP($D22,LVTable,3,FALSE),DefThrAsset),IFERROR(VLOOKUP($D22,LVTable,3,FALSE),DefThrAsset)/$AI22,1)))) | AK22: =IF($B22="","",$AE22*$AJ22)
A23: =IF($B23="","",ROW()-4) | K23: =IF($B23="","",IF(ISNUMBER($J23),$J23,$I23)) | L23: =IF($B23="","",IFERROR(VLOOKUP($G23,FXRates,4,FALSE),1)) | M23: =IF($B23="","",$H23*$K23*$L23) | O23: =IF($B23="","",IF($D23=CashLabel,IF(ISNUMBER($N23),$N23,1),MIN(IF(ISNUMBER($N23),$N23,IFERROR(VLOOKUP($D23,LVTable,2,FALSE),0)),LVCap))) | P23: =IF($B23="","",$M23*$O23) | Q23: =IF($B23="","",IFERROR(VLOOKUP($G23,FXRates,5,FALSE),$G23)) | R23: =IF($B23="","",IF($D23=CashLabel,"",SUMIFS($P$5:$P$204,$B$5:$B$204,$B23,$D$5:$D$204,"<>"&CashLabel)/ConcDenom)) | S23: =IF($B23="","",IF($D23=CashLabel,"",SUMIFS($P$5:$P$204,$E$5:$E$204,$E23,$D$5:$D$204,"<>"&CashLabel)/ConcDenom)) | T23: =IF($B23="","",IF($D23=CashLabel,"",SUMIFS($P$5:$P$204,$F$5:$F$204,$F23,$D$5:$D$204,"<>"&CashLabel)/ConcDenom)) | U23: =IF($B23="","",IF($D23=CashLabel,"",SUMIFS($P$5:$P$204,$D$5:$D$204,$D23,$D$5:$D$204,"<>"&CashLabel)/ConcDenom)) | V23: =IF($B23="","",IF($D23=CashLabel,1,IF($R23>ThrSingle,ThrSingle/$R23,1))) | W23: =IF($B23="","",IF($D23=CashLabel,1,IF($S23>ThrIssuer,ThrIssuer/$S23,1))) | X23: =IF($B23="","",IF($D23=CashLabel,1,IF($T23>IFERROR(VLOOKUP($F23,CountryThr,2,FALSE),DefThrCountry),IFERROR(VLOOKUP($F23,CountryThr,2,FALSE),DefThrCountry)/$T23,1))) | Y23: =IF($B23="","",IF($D23=CashLabel,1,IF($U23>IFERROR(VLOOKUP($D23,LVTable,3,FALSE),DefThrAsset),IFERROR(VLOOKUP($D23,LVTable,3,FALSE),DefThrAsset)/$U23,1))) | Z23: =IF($B23="","",IF($D23=CashLabel,1,MIN($V23:$Y23))) | AA23: =IF($B23="","",$P23*$Z23) | AB23: =IF($B23="","",$P23-$AA23) | AD23: =IF($B23="","",$M23*(1+IF(ISNUMBER($AC23),$AC23,0))) | AE23: =IF($B23="","",$AD23*$O23) | AF23: =IF($B23="","",IF($D23=CashLabel,"",SUMIFS($AE$5:$AE$204,$B$5:$B$204,$B23,$D$5:$D$204,"<>"&CashLabel)/ConcDenomStr)) | AG23: =IF($B23="","",IF($D23=CashLabel,"",SUMIFS($AE$5:$AE$204,$E$5:$E$204,$E23,$D$5:$D$204,"<>"&CashLabel)/ConcDenomStr)) | AH23: =IF($B23="","",IF($D23=CashLabel,"",SUMIFS($AE$5:$AE$204,$F$5:$F$204,$F23,$D$5:$D$204,"<>"&CashLabel)/ConcDenomStr)) | AI23: =IF($B23="","",IF($D23=CashLabel,"",SUMIFS($AE$5:$AE$204,$D$5:$D$204,$D23,$D$5:$D$204,"<>"&CashLabel)/ConcDenomStr)) | AJ23: =IF($B23="","",IF($D23=CashLabel,1,MIN(IF($AF23>ThrSingle,ThrSingle/$AF23,1),IF($AG23>ThrIssuer,ThrIssuer/$AG23,1),IF($AH23>IFERROR(VLOOKUP($F23,CountryThr,2,FALSE),DefThrCountry),IFERROR(VLOOKUP($F23,CountryThr,2,FALSE),DefThrCountry)/$AH23,1),IF($AI23>IFERROR(VLOOKUP($D23,LVTable,3,FALSE),DefThrAsset),IFERROR(VLOOKUP($D23,LVTable,3,FALSE),DefThrAsset)/$AI23,1)))) | AK23: =IF($B23="","",$AE23*$AJ23)
